Workbook

Sheet How to use
A1: Screenshot review - images from 2021, 2022 and 2023
A3: Oxford Abstracts help centre. Generated 31 July 2026 from the article source files.
A5: What this is
A6: 134 articles contain at least one screenshot dated 2021, 2022 or 2023 - 833 images in total.
A7: Go through each article, look at the images, and decide whether each still matches the
A8: current interface. Update it or leave it. Record the decision on the Articles tab.
A10: About the dates
A11: The date is taken from the image filename, which records when it was uploaded to the old
A12: knowledge base - not when the screenshot was taken. So it means "no newer than". An image
A13: dated 2022 cannot show a newer interface than 2022, but it may show an older one.
A15: The tabs
A16: Articles one row per article. This is the work list - fill in the yellow columns.
... A22: Fill in these four columns only (shaded yellow)
A23: Decision | B23: Reviewed by | C23: Date reviewed | D23: Notes
A24: Update | B24: A. Reviewer | C24: 2026-08-04 | D24: Three images show the old dashboard; two are still fine
A25: Example row - shows the expected format. Decision must be Update, Leave as is, or Done.
A27: Progress
A28: Articles to review | B28: =COUNTA(Articles!A2:A135)
A29: Decision recorded | B29: =COUNTA(Articles!K2:K135)
A30: Still to do | B30: =B28-B29
A32: Marked "Update" | B32: =COUNTIF(Articles!K2:K135,"Update")
A33: Marked "Leave as is" | B33: =COUNTIF(Articles!K2:K135,"Leave as is")
A34: Marked "Done" | B34: =COUNTIF(Articles!K2:K135,"Done")
A36: Images from 2021-2023 | B36: =SUM(Articles!G2:G135)

Sheet Articles
A1: Article | B1: Section | C1: Link | D1: 2021 | E1: 2022 | F1: 2023 | G1: Total 21-23 | H1: All images | I1: Oldest | J1: Older undated | K1: Decision | L1: Reviewed by | M1: Date reviewed | N1: Notes | O1: Tickets/yr
A2: Creating a certificate | B2: 09-add-ons | C2: open | D2: 0 | E2: 0 | F2: 33 | G2: =SUM(D2:F2) | H2: 37 | I2: 2023-08 | J2: 1 | O2: 61
A3: Creating your delegate registration tickets for your event | B3: 07-delegate-registration | C3: open | D3: 0 | E3: 21 | F3: 8 | G3: =SUM(D3:F3) | H3: 30 | I3: 2022-11 | J3: 0
A4: Using the chat and controlling notifications | B4: 14-for-attendees-exhibitors | C4: open | D4: 20 | E4: 5 | F4: 0 | G4: =SUM(D4:F4) | H4: 30 | I4: 2021-06 | J4: 5
A5: Creating your delegate registration form | B5: 07-delegate-registration | C5: open | D5: 0 | E5: 22 | F5: 0 | G5: =SUM(D5:F5) | H5: 23 | I5: 2022-11 | J5: 0
A6: Setting up your program - configuration | B6: 08-conference-platform | C6: open | D6: 9 | E6: 4 | F6: 5 | G6: =SUM(D6:F6) | H6: 31 | I6: 2021-03 | J6: 13
A7: Submission question types | B7: 02-submissions | C7: open | D7: 12 | E7: 5 | F7: 0 | G7: =SUM(D7:F7) | H7: 37 | I7: 2021-03 | J7: 20
A8: Setting up payment providers for delegate registration | B8: 07-delegate-registration | C8: open | D8: 0 | E8: 0 | F8: 17 | G8: =SUM(D8:F8) | H8: 23 | I8: 2023-01 | J8: 1
A9: Setting up the homepage for your conference | B9: 08-conference-platform | C9: open | D9: 0 | E9: 0 | F9: 17 | G9: =SUM(D9:F9) | H9: 18 | I9: 2023-09 | J9: 0
A10: How admins can amend existing delegate registration orders | B10: 07-delegate-registration | C10: open | D10: 0 | E10: 0 | F10: 16 | G10: =SUM(D10:F10) | H10: 17 | I10: 2023-06 | J10: 0
A11: Configuring invoices and receipts for delegate registration | B11: 07-delegate-registration | C11: open | D11: 0 | E11: 0 | F11: 16 | G11: =SUM(D11:F11) | H11: 20 | I11: 2023-11 | J11: 0
A12: Completing a Symposium review | B12: 13-for-reviewers-committee | C12: open | D12: 1 | E12: 14 | F12: 0 | G12: =SUM(D12:F12) | H12: 16 | I12: 2021-09 | J12: 1
A13: Managing orders and edit the attendee table | B13: 07-delegate-registration | C13: open | D13: 0 | E13: 14 | F13: 0 | G13: =SUM(D13:F13) | H13: 20 | I13: 2022-11 | J13: 0
A14: Adding a session-less submission to the title listing | B14: 06-programme-exports-reports | C14: open | D14: 0 | E14: 13 | F14: 0 | G14: =SUM(D14:F14) | H14: 15 | I14: 2022-06 | J14: 1
A15: The submissions table (including incomplete submissions) | B15: 02-submissions | C15: open | D15: 5 | E15: 1 | F15: 6 | G15: =SUM(D15:F15) | H15: 18 | I15: 2021-02 | J15: 5 | O15: 21
A16: Creating announcements on conference | B16: 08-conference-platform | C16: open | D16: 0 | E16: 0 | F16: 12 | G16: =SUM(D16:F16) | H16: 12 | I16: 2023-03 | J16: 0
A17: The authors and affiliations question | B17: 02-submissions | C17: open | D17: 11 | E17: 0 | F17: 0 | G17: =SUM(D17:F17) | H17: 17 | I17: 2021-02 | J17: 5 | O17: 30
A18: Setting up your Zoom integration | B18: 08-conference-platform | C18: open | D18: 11 | E18: 0 | F18: 0 | G18: =SUM(D18:F18) | H18: 11 | I18: 2021-09 | J18: 0 | O18: 24
A19: Exhibitor space - setting up and managing your booth | B19: 14-for-attendees-exhibitors | C19: open | D19: 6 | E19: 5 | F19: 0 | G19: =SUM(D19:F19) | H19: 11 | I19: 2021-11 | J19: 0
A20: Design the decision form | B20: 04-decisions | C20: open | D20: 10 | E20: 0 | F20: 0 | G20: =SUM(D20:F20) | H20: 21 | I20: 2021-02 | J20: 9
A21: Creating and paying for a new event | B21: 01-getting-started | C21: open | D21: 10 | E21: 0 | F21: 0 | G21: =SUM(D21:F21) | H21: 13 | I21: 2021-03 | J21: 3 | O21: 73
A22: Professional Conference - the poster gallery | B22: 08-conference-platform | C22: open | D22: 9 | E22: 1 | F22: 0 | G22: =SUM(D22:F22) | H22: 11 | I22: 2021-03 | J22: 0
A23: Colour coding your event | B23: 08-conference-platform | C23: open | D23: 10 | E23: 0 | F23: 0 | G23: =SUM(D23:F23) | H23: 20 | I23: 2021-04 | J23: 10
A24: Viewing sessions and content in the conference program | B24: 14-for-attendees-exhibitors | C24: open | D24: 8 | E24: 2 | F24: 0 | G24: =SUM(D24:F24) | H24: 10 | I24: 2021-06 | J24: 0
A25: Adding chair's email addresses | B25: 06-programme-exports-reports | C25: open | D25: 0 | E25: 10 | F25: 0 | G25: =SUM(D25:F25) | H25: 10 | I25: 2022-06 | J25: 0
A26: Editing automated emails for delegate registration | B26: 07-delegate-registration | C26: open | D26: 0 | E26: 0 | F26: 10 | G26: =SUM(D26:F26) | H26: 11 | I26: 2023-12 | J26: 0
A27: Designing the review form | B27: 03-reviewing | C27: open | D27: 9 | E27: 0 | F27: 0 | G27: =SUM(D27:F27) | H27: 13 | I27: 2021-02 | J27: 4
A28: Setting up a Multi-stage event | B28: 02-submissions | C28: open | D28: 2 | E28: 7 | F28: 0 | G28: =SUM(D28:F28) | H28: 10 | I28: 2021-04 | J28: 1
A29: Managing Symposia | B29: 09-add-ons | C29: open | D29: 9 | E29: 0 | F29: 0 | G29: =SUM(D29:F29) | H29: 12 | I29: 2021-05 | J29: 3
A30: Downloading your program and session books | B30: 06-programme-exports-reports | C30: open | D30: 0 | E30: 9 | F30: 0 | G30: =SUM(D30:F30) | H30: 10 | I30: 2022-01 | J30: 1
A31: Editing your delegate registration ticket details page | B31: 07-delegate-registration | C31: open | D31: 0 | E31: 0 | F31: 9 | G31: =SUM(D31:F31) | H31: 10 | I31: 2023-05 | J31: 0
A32: Working with tables | B32: 01-getting-started | C32: open | D32: 6 | E32: 2 | F32: 0 | G32: =SUM(D32:F32) | H32: 13 | I32: 2021-02 | J32: 5
A33: Sending and scheduling emails | B33: 05-emails | C33: open | D33: 7 | E33: 0 | F33: 1 | G33: =SUM(D33:F33) | H33: 10 | I33: 2021-02 | J33: 2
A34: Attaching content to sessions | B34: 08-conference-platform | C34: open | D34: 7 | E34: 1 | F34: 0 | G34: =SUM(D34:F34) | H34: 8 | I34: 2021-03 | J34: 0
A35: Creating a session | B35: 08-conference-platform | C35: open | D35: 8 | E35: 0 | F35: 0 | G35: =SUM(D35:F35) | H35: 9 | I35: 2021-03 | J35: 1 | O35: 37
A36: Setting up your program - display | B36: 08-conference-platform | C36: open | D36: 8 | E36: 0 | F36: 0 | G36: =SUM(D36:F36) | H36: 10 | I36: 2021-03 | J36: 2
A37: Setting up your conference program account | B37: 14-for-attendees-exhibitors | C37: open | D37: 8 | E37: 0 | F37: 0 | G37: =SUM(D37:F37) | H37: 8 | I37: 2021-06 | J37: 0
A38: Professional Conference - branding | B38: 08-conference-platform | C38: open | D38: 5 | E38: 3 | F38: 0 | G38: =SUM(D38:F38) | H38: 8 | I38: 2021-08 | J38: 0
A39: Sending emails from tables | B39: 05-emails | C39: open | D39: 1 | E39: 7 | F39: 0 | G39: =SUM(D39:F39) | H39: 8 | I39: 2021-11 | J39: 0
A40: Professional Conference - exhibitor space - admin set up | B40: 08-conference-platform | C40: open | D40: 5 | E40: 3 | F40: 0 | G40: =SUM(D40:F40) | H40: 9 | I40: 2021-11 | J40: 0
...

Sheet Images
A1: Article | B1: Section | C1: Image # in article | D1: Date | E1: Appears under | F1: Filename
A2: Abstract books | B2: 06-programme-exports-reports | C2: 1 | D2: 2021-03-01 | E2: You can easily create a range of abstract books, which include the responses to various fi | F2: undefined-mar-01-2021-10-19-04-87-am-8cdff547.webp
A3: Abstract books | B3: 06-programme-exports-reports | C3: 2 | D3: 2021-03-01 | E3: You can easily create a range of abstract books, which include the responses to various fi | F3: undefined-mar-01-2021-10-18-29-28-am-de87c3c6.webp
A4: Abstract books | B4: 06-programme-exports-reports | C4: 3 | D4: 2021-03-01 | E4: You can easily create a range of abstract books, which include the responses to various fi | F4: undefined-mar-01-2021-10-20-41-03-am-cc30fe43.webp
A5: Accessing reviews from previous stages | B5: 02-submissions | C5: 1 | D5: 2022-03-16 | E5: In the example below, there are none. | F5: undefined-mar-16-2022-04-07-10-94-pm-62df54bb.webp
A6: Accessing your reviews | B6: 12-for-submitters | C6: 1 | D6: 2022-07-12 | E6: This guide explains how to view reviewer feedback on your submission. Review access depend | F6: screenshot-2022-07-12-at-16-30-30-png-d220fcf6.webp
A7: Accessing your reviews | B7: 12-for-submitters | C7: 2 | D7: 2022-07-12 | E7: This guide explains how to view reviewer feedback on your submission. Review access depend | F7: screenshot-2022-07-12-at-16-30-40-png-bc59335d.webp
A8: Accessing your reviews | B8: 12-for-submitters | C8: 3 | D8: 2023-03-09 | E8: This guide explains how to view reviewer feedback on your submission. Review access depend | F8: screenshot-2023-03-09-at-16-11-57-png-bc72d977.webp
A9: Account administration dashboard | B9: 11-account-administration | C9: 2 | D9: 2021-02-18 | E9: Find out how to access all the tools available to you as an account administrator. | F9: image-png-feb-18-2021-04-22-20-24-pm-0ebf4f0c.webp
A10: Adding a session-less submission to the title listing | B10: 06-programme-exports-reports | C10: 2 | D10: 2022-06-09 | E10: Learn how to add submission titles into a session without having them included in the prog | F10: screenshot-2022-06-09-at-13-00-28-f48ef727.webp
A11: Adding a session-less submission to the title listing | B11: 06-programme-exports-reports | C11: 3 | D11: 2022-06-09 | E11: Learn how to add submission titles into a session without having them included in the prog | F11: screenshot-2022-06-09-at-13-01-36-17808101.webp
A12: Adding a session-less submission to the title listing | B12: 06-programme-exports-reports | C12: 4 | D12: 2022-06-09 | E12: Learn how to add submission titles into a session without having them included in the prog | F12: screenshot-2022-06-09-at-13-02-22-9572a184.webp
A13: Adding a session-less submission to the title listing | B13: 06-programme-exports-reports | C13: 5 | D13: 2022-06-09 | E13: Learn how to add submission titles into a session without having them included in the prog | F13: screenshot-2022-06-09-at-13-04-06-7c2cb4d9.webp
... A834: Your personal dashboard | B834: 01-getting-started | C834: 9 | D834: 2021-02-18 | E834: Delegates | F834: undefined-feb-18-2021-05-03-28-35-pm-8f37c5e7.webp

Sheet Older undated
A1: These 16 articles have images with no date in the filename. They come from the Freshdesk knowledge base, which predates HubSpot, so they are almost certainly older than anything on the Articles tab.
A3: Article | B3: Section | C3: Link | D3: Undated images | E3: All images | F3: Newer images present
A4: Assigning categories to committee members | B4: 04-decisions | C4: open | D4: 7 | E4: 7
A5: Editing a Symposium | B5: 12-for-submitters | C5: open | D5: 6 | E5: 6
A6: Combined word count | B6: 02-submissions | C6: open | D6: 4 | E6: 5 | F6: 1
A7: Event details | B7: 01-getting-started | C7: open | D7: 3 | E7: 6 | F7: 3
A8: Restricting who can submit by email | B8: 02-submissions | C8: open | D8: 3 | E8: 4 | F8: 1
A9: Creating your event website | B9: 08-conference-platform | C9: open | D9: 3 | E9: 10 | F9: 7
A10: Showing reviews to submitters | B10: 03-reviewing | C10: open | D10: 2 | E10: 3 | F10: 1
A11: Opening and closing decision making | B11: 04-decisions | C11: open | D11: 2 | E11: 6 | F11: 4
A12: Emailing session chairs from the dashboard | B12: 05-emails | C12: open | D12: 2 | E12: 2
A13: Abstract management checklist | B13: 01-getting-started | C13: open | D13: 1 | E13: 1
A14: Different types of users in the system | B14: 01-getting-started | C14: open | D14: 1 | E14: 1
A15: Opening and closing reviewing | B15: 03-reviewing | C15: open | D15: 1 | E15: 7 | F15: 6
A16: Creating a backup of your conference data | B16: 06-programme-exports-reports | C16: open | D16: 1 | E16: 2 | F16: 1
A17: Deleting your Oxford Abstracts account | B17: 11-account-administration | C17: open | D17: 1 | E17: 5 | F17: 4
A18: How do i contact the event administrator? | B18: 14-for-attendees-exhibitors | C18: open | D18: 1 | E18: 1
A19: Payment error | B19: 14-for-attendees-exhibitors | C19: open | D19: 1 | E19: 1
